<mujoco model="2 dof ball">
    <compiler angle="radian"/>
    <option timestep="0.002" iterations="1" ls_iterations="4" solver="Newton" gravity="0 0 -9.81">
        <flag eulerdamp="disable"/>
    </option>
    <worldbody>
        <light cutoff="100" diffuse="1 1 1" dir="-0 0 -1.3" directional="true" exponent="1" pos="0 0 1.3" specular=".1 .1 .1"/>
        <geom conaffinity="1" condim="3" name="floor" pos="0 0 0" rgba="0.8 0.9 0.8 1" size="20 20 .125" type="plane" material="MatPlane" group="1"/>
        <body name="ball" pos="0 0 0.2">
            <camera name="fwd" pos="0 0.11 0" xyaxes="1 0 0 0 0 1"/>
            <joint axis="1 0 0" pos="0 0 -0.1" limited="false" name="rootx" type="slide"/>
            <joint axis="0 1 0" pos="0 0 -0.1" limited="false" name="rooty" type="slide"/>
            <joint axis="0 0 1" pos="0 0 -0.1" limited="false" name="rotz" type="hinge"/>
            <geom name="ball_geom" size="0.1 0.1" type="capsule" conaffinity="0" contype="1"/>
        </body>
    </worldbody>
    
    <actuator>
        <motor ctrllimited="true" ctrlrange="-1.0 1.0" gear="50.0" joint="rootx"/>
        <motor ctrllimited="true" ctrlrange="-1.0 1.0" gear="50.0" joint="rooty"/>
        <motor ctrllimited="true" ctrlrange="-1.0 1.0" gear="50.0" joint="rotz"/>
    </actuator>

    <asset>
        <texture type="skybox" builtin="gradient" rgb1="1.0 1.0 1.0" rgb2="1.0 1.0 1.0" width="512" height="512"/>
        <texture name="plane" type="2d" builtin="flat" rgb1="1 1 1" rgb2="1 1 1" width="512" height="512" mark="cross" markrgb="0 0 0"/>
        <material name="MatPlane" reflectance="0.0" texture="plane" texrepeat="3 3" texuniform="true"/>
    </asset>
    
    <!-- <asset>
        <texture type="skybox" builtin="gradient" rgb1=".4 .5 .6" rgb2="0 0 0"
            width="100" height="100"/>
        <texture builtin="flat" height="1278" mark="cross" markrgb="1 1 1" name="texgeom" random="0.01" rgb1="0.8 0.6 0.4" rgb2="0.8 0.6 0.4" type="cube" width="127"/>
        <texture type="2d" name="texplane" builtin="checker" mark="edge" rgb1="0.2 0.3 0.4" rgb2="0.1 0.2 0.3"
        markrgb="0.8 0.8 0.8" width="100" height="100"/>
        <material name="MatPlane" texture="texplane" texuniform="true" texrepeat="5 5" reflectance="0.2"/>
        <material name="geom" texture="texgeom" texuniform="true"/>
    </asset> -->
</mujoco>